Workbook

Sheet MarketShare
A1: date | B1: interval | C1: interval_dose | D1: interval_first | E1: interval_second | F1: interval_boost | G1: interval_sv_primary | H1: interval_az_primary | I1: interval_sp_primary | J1: interval_pf_primary | K1: interval_moderna_primary | L1: interval_sv_boost | M1: interval_az_boost | N1: interval_sp_boost | O1: interval_pf_boost | P1: interval_moderna_boost | Q1: share_sv_primary | R1: share_az_primary | S1: share_sp_primary | T1: share_pf_primary | U1: share_moderna_primary | V1: share_sv_boost | W1: share_az_boost | X1: share_sp_boost | Y1: share_pf_boost | Z1: share_moderna_boost
A2: 44255
A3: 44263 | B3: =A3-A2 -> 8 | C3: =DataExtract!B3-DataExtract!B2 -> 29900 | D3: =DataExtract!C3-DataExtract!C2 -> 29900 | E3: =DataExtract!D3-DataExtract!D2 -> 0 | F3: =DataExtract!E3-DataExtract!E2 -> 0 | G3: =(DataExtract!K3+DataExtract!P3)-(DataExtract!K2+DataExtract!P2) -> 0 | H3: =(DataExtract!L3+DataExtract!Q3)-(DataExtract!L2+DataExtract!Q2) -> 0 | I3: =(DataExtract!M3+DataExtract!R3)-(DataExtract!M2+DataExtract!R2) -> 0 | J3: =(DataExtract!N3+DataExtract!S3)-(DataExtract!N2+DataExtract!S2) -> 0 | K3: =(DataExtract!O3+DataExtract!T3)-(DataExtract!O2+DataExtract!T2) -> 0 | L3: =DataExtract!U3-DataExtract!U2 -> 0 | M3: =DataExtract!V3-DataExtract!V2 -> 0 | N3: =DataExtract!W3-DataExtract!W2 -> 0 | O3: =DataExtract!X3-DataExtract!X2 -> 0 | P3: =DataExtract!Y3-DataExtract!Y2 -> 0 | Q3: 1 | R3: 0 | S3: 0 | T3: 0 | U3: 0 | V3: 0 | W3: 0 | X3: 0 | Y3: 0 | Z3: 0
A4: 44270 | B4: =A4-A3 -> 7 | C4: =DataExtract!B4-DataExtract!B3 -> 20488 | D4: =DataExtract!C4-DataExtract!C3 -> 20488 | E4: =DataExtract!D4-DataExtract!D3 -> 0 | F4: =DataExtract!E4-DataExtract!E3 -> 0 | G4: =(DataExtract!K4+DataExtract!P4)-(DataExtract!K3+DataExtract!P3) -> 0 | H4: =(DataExtract!L4+DataExtract!Q4)-(DataExtract!L3+DataExtract!Q3) -> 0 | I4: =(DataExtract!M4+DataExtract!R4)-(DataExtract!M3+DataExtract!R3) -> 0 | J4: =(DataExtract!N4+DataExtract!S4)-(DataExtract!N3+DataExtract!S3) -> 0 | K4: =(DataExtract!O4+DataExtract!T4)-(DataExtract!O3+DataExtract!T3) -> 0 | L4: =DataExtract!U4-DataExtract!U3 -> 0 | M4: =DataExtract!V4-DataExtract!V3 -> 0 | N4: =DataExtract!W4-DataExtract!W3 -> 0 | O4: =DataExtract!X4-DataExtract!X3 -> 0 | P4: =DataExtract!Y4-DataExtract!Y3 -> 0 | Q4: 1 | R4: 0 | S4: 0 | T4: 0 | U4: 0 | V4: 0 | W4: 0 | X4: 0 | Y4: 0 | Z4: 0
A5: 44277 | B5: =A5-A4 -> 7 | C5: =DataExtract!B5-DataExtract!B4 -> 34853 | D5: =DataExtract!C5-DataExtract!C4 -> 32424 | E5: =DataExtract!D5-DataExtract!D4 -> 2429 | F5: =DataExtract!E5-DataExtract!E4 -> 0 | G5: =(DataExtract!K5+DataExtract!P5)-(DataExtract!K4+DataExtract!P4) -> 0 | H5: =(DataExtract!L5+DataExtract!Q5)-(DataExtract!L4+DataExtract!Q4) -> 0 | I5: =(DataExtract!M5+DataExtract!R5)-(DataExtract!M4+DataExtract!R4) -> 0 | J5: =(DataExtract!N5+DataExtract!S5)-(DataExtract!N4+DataExtract!S4) -> 0 | K5: =(DataExtract!O5+DataExtract!T5)-(DataExtract!O4+DataExtract!T4) -> 0 | L5: =DataExtract!U5-DataExtract!U4 -> 0 | M5: =DataExtract!V5-DataExtract!V4 -> 0 | N5: =DataExtract!W5-DataExtract!W4 -> 0 | O5: =DataExtract!X5-DataExtract!X4 -> 0 | P5: =DataExtract!Y5-DataExtract!Y4 -> 0 | Q5: 1 | R5: 0 | S5: 0 | T5: 0 | U5: 0 | V5: 0 | W5: 0 | X5: 0 | Y5: 0 | Z5: 0
A6: 44284 | B6: =A6-A5 -> 7 | C6: =DataExtract!B6-DataExtract!B5 -> 81117 | D6: =DataExtract!C6-DataExtract!C5 -> 58269 | E6: =DataExtract!D6-DataExtract!D5 -> 22848 | F6: =DataExtract!E6-DataExtract!E5 -> 0 | G6: =(DataExtract!K6+DataExtract!P6)-(DataExtract!K5+DataExtract!P5) -> 155795 | H6: =(DataExtract!L6+DataExtract!Q6)-(DataExtract!L5+DataExtract!Q5) -> 10563 | I6: =(DataExtract!M6+DataExtract!R6)-(DataExtract!M5+DataExtract!R5) -> 0 | J6: =(DataExtract!N6+DataExtract!S6)-(DataExtract!N5+DataExtract!S5) -> 0 | K6: =(DataExtract!O6+DataExtract!T6)-(DataExtract!O5+DataExtract!T5) -> 0 | L6: =DataExtract!U6-DataExtract!U5 -> 0 | M6: =DataExtract!V6-DataExtract!V5 -> 0 | N6: =DataExtract!W6-DataExtract!W5 -> 0 | O6: =DataExtract!X6-DataExtract!X5 -> 0 | P6: =DataExtract!Y6-DataExtract!Y5 -> 0 | Q6: =G6/SUM($G6:$K6) -> 0.93650441 | R6: =H6/SUM($G6:$K6) -> 0.063495594 | S6: 0 | T6: 0 | U6: 0 | V6: 0 | W6: 0 | X6: 0 | Y6: 0 | Z6: 0
A7: 44291 | B7: =A7-A6 -> 7 | C7: =DataExtract!B7-DataExtract!B6 -> 128523 | D7: =DataExtract!C7-DataExtract!C6 -> 106769 | E7: =DataExtract!D7-DataExtract!D6 -> 21754 | F7: =DataExtract!E7-DataExtract!E6 -> 0 | G7: =(DataExtract!K7+DataExtract!P7)-(DataExtract!K6+DataExtract!P6) -> 97068 | H7: =(DataExtract!L7+DataExtract!Q7)-(DataExtract!L6+DataExtract!Q6) -> 31455 | I7: =(DataExtract!M7+DataExtract!R7)-(DataExtract!M6+DataExtract!R6) -> 0 | J7: =(DataExtract!N7+DataExtract!S7)-(DataExtract!N6+DataExtract!S6) -> 0 | K7: =(DataExtract!O7+DataExtract!T7)-(DataExtract!O6+DataExtract!T6) -> 0 | L7: =DataExtract!U7-DataExtract!U6 -> 0 | M7: =DataExtract!V7-DataExtract!V6 -> 0 | N7: =DataExtract!W7-DataExtract!W6 -> 0 | O7: =DataExtract!X7-DataExtract!X6 -> 0 | P7: =DataExtract!Y7-DataExtract!Y6 -> 0 | Q7: =G7/SUM($G7:$K7) -> 0.75525781 | R7: =H7/SUM($G7:$K7) -> 0.24474219 | S7: 0 | T7: 0 | U7: 0 | V7: 0 | W7: 0 | X7: 0 | Y7: 0 | Z7: 0
A8: 44298 | B8: =A8-A7 -> 7 | C8: =DataExtract!B8-DataExtract!B7 -> 283651 | D8: =DataExtract!C8-DataExtract!C7 -> 257365 | E8: =DataExtract!D8-DataExtract!D7 -> 26286 | F8: =DataExtract!E8-DataExtract!E7 -> 0 | G8: =(DataExtract!K8+DataExtract!P8)-(DataExtract!K7+DataExtract!P7) -> 271393 | H8: =(DataExtract!L8+DataExtract!Q8)-(DataExtract!L7+DataExtract!Q7) -> 12258 | I8: =(DataExtract!M8+DataExtract!R8)-(DataExtract!M7+DataExtract!R7) -> 0 | J8: =(DataExtract!N8+DataExtract!S8)-(DataExtract!N7+DataExtract!S7) -> 0 | K8: =(DataExtract!O8+DataExtract!T8)-(DataExtract!O7+DataExtract!T7) -> 0 | L8: =DataExtract!U8-DataExtract!U7 -> 0 | M8: =DataExtract!V8-DataExtract!V7 -> 0 | N8: =DataExtract!W8-DataExtract!W7 -> 0 | O8: =DataExtract!X8-DataExtract!X7 -> 0 | P8: =DataExtract!Y8-DataExtract!Y7 -> 0 | Q8: =G8/SUM($G8:$K8) -> 0.95678492 | R8: =H8/SUM($G8:$K8) -> 0.043215078 | S8: 0 | T8: 0 | U8: 0 | V8: 0 | W8: 0 | X8: 0 | Y8: 0 | Z8: 0
A9: 44305 | B9: =A9-A8 -> 7 | C9: =DataExtract!B9-DataExtract!B8 -> 87678 | D9: =DataExtract!C9-DataExtract!C8 -> 66610 | E9: =DataExtract!D9-DataExtract!D8 -> 21068 | F9: =DataExtract!E9-DataExtract!E8 -> 0 | G9: =(DataExtract!K9+DataExtract!P9)-(DataExtract!K8+DataExtract!P8) -> 84492 | H9: =(DataExtract!L9+DataExtract!Q9)-(DataExtract!L8+DataExtract!Q8) -> 3186 | I9: =(DataExtract!M9+DataExtract!R9)-(DataExtract!M8+DataExtract!R8) -> 0 | J9: =(DataExtract!N9+DataExtract!S9)-(DataExtract!N8+DataExtract!S8) -> 0 | K9: =(DataExtract!O9+DataExtract!T9)-(DataExtract!O8+DataExtract!T8) -> 0 | L9: =DataExtract!U9-DataExtract!U8 -> 0 | M9: =DataExtract!V9-DataExtract!V8 -> 0 | N9: =DataExtract!W9-DataExtract!W8 -> 0 | O9: =DataExtract!X9-DataExtract!X8 -> 0 | P9: =DataExtract!Y9-DataExtract!Y8 -> 0 | Q9: =G9/SUM($G9:$K9) -> 0.96366249 | R9: =H9/SUM($G9:$K9) -> 0.036337508 | S9: 0 | T9: 0 | U9: 0 | V9: 0 | W9: 0 | X9: 0 | Y9: 0 | Z9: 0
A10: 44312 | B10: =A10-A9 -> 7 | C10: =DataExtract!B10-DataExtract!B9 -> 560822 | D10: =DataExtract!C10-DataExtract!C9 -> 440563 | E10: =DataExtract!D10-DataExtract!D9 -> 120259 | F10: =DataExtract!E10-DataExtract!E9 -> 0 | L10: =DataExtract!U10-DataExtract!U9 -> 0 | M10: =DataExtract!V10-DataExtract!V9 -> 0 | N10: =DataExtract!W10-DataExtract!W9 -> 0 | O10: =DataExtract!X10-DataExtract!X9 -> 0 | P10: =DataExtract!Y10-DataExtract!Y9 -> 0 | Q10: =Q9 -> 0.96366249 | R10: =R9 -> 0.036337508 | S10: 0 | T10: 0 | U10: 0 | V10: 0 | W10: 0 | X10: 0 | Y10: 0 | Z10: 0
A11: 44319 | B11: =A11-A10 -> 7 | C11: =DataExtract!B11-DataExtract!B10 -> 271585 | D11: =DataExtract!C11-DataExtract!C10 -> 93683 | E11: =DataExtract!D11-DataExtract!D10 -> 177902 | F11: =DataExtract!E11-DataExtract!E10 -> 0 | L11: =DataExtract!U11-DataExtract!U10 -> 0 | M11: =DataExtract!V11-DataExtract!V10 -> 0 | N11: =DataExtract!W11-DataExtract!W10 -> 0 | O11: =DataExtract!X11-DataExtract!X10 -> 0 | P11: =DataExtract!Y11-DataExtract!Y10 -> 0 | Q11: =Q10 -> 0.96366249 | R11: =R10 -> 0.036337508 | S11: 0 | T11: 0 | U11: 0 | V11: 0 | W11: 0 | X11: 0 | Y11: 0 | Z11: 0
A12: 44326 | B12: =A12-A11 -> 7 | C12: =DataExtract!B12-DataExtract!B11 -> 399837 | D12: =DataExtract!C12-DataExtract!C11 -> 259921 | E12: =DataExtract!D12-DataExtract!D11 -> 139916 | F12: =DataExtract!E12-DataExtract!E11 -> 0 | L12: =DataExtract!U12-DataExtract!U11 -> 0 | M12: =DataExtract!V12-DataExtract!V11 -> 0 | N12: =DataExtract!W12-DataExtract!W11 -> 0 | O12: =DataExtract!X12-DataExtract!X11 -> 0 | P12: =DataExtract!Y12-DataExtract!Y11 -> 0 | Q12: =Q11 -> 0.96366249 | R12: =R11 -> 0.036337508 | S12: 0 | T12: 0 | U12: 0 | V12: 0 | W12: 0 | X12: 0 | Y12: 0 | Z12: 0
A13: 44333 | B13: =A13-A12 -> 7 | C13: =DataExtract!B13-DataExtract!B12 -> 442541 | D13: =DataExtract!C13-DataExtract!C12 -> 155042 | E13: =DataExtract!D13-DataExtract!D12 -> 287499 | F13: =DataExtract!E13-DataExtract!E12 -> 0 | G13: =(DataExtract!K13+DataExtract!P13)-(DataExtract!K9+DataExtract!P9) -> 1623127 | H13: =(DataExtract!L13+DataExtract!Q13)-(DataExtract!L9+DataExtract!Q9) -> 51658 | I13: =(DataExtract!M13+DataExtract!R13)-(DataExtract!M9+DataExtract!R9) -> 0 | J13: =(DataExtract!N13+DataExtract!S13)-(DataExtract!N9+DataExtract!S9) -> 0 | K13: =(DataExtract!O13+DataExtract!T13)-(DataExtract!O9+DataExtract!T9) -> 0 | L13: =DataExtract!U13-DataExtract!U12 -> 0 | M13: =DataExtract!V13-DataExtract!V12 -> 0 | N13: =DataExtract!W13-DataExtract!W12 -> 0 | O13: =DataExtract!X13-DataExtract!X12 -> 0 | P13: =DataExtract!Y13-DataExtract!Y12 -> 0 | Q13: =G13/SUM($G13:$K13) -> 0.96915544 | R13: =H13/SUM($G13:$K13) -> 0.030844556 | S13: =I13/SUM($G13:$K13) -> 0 | T13: =J13/SUM($G13:$K13) -> 0 | U13: =K13/SUM($G13:$K13) -> 0 | V13: 0 | W13: 0 | X13: 0 | Y13: 0 | Z13: 0
A14: 44340 | B14: =A14-A13 -> 7 | C14: =DataExtract!B14-DataExtract!B13 -> 683318 | D14: =DataExtract!C14-DataExtract!C13 -> 523089 | E14: =DataExtract!D14-DataExtract!D13 -> 160229 | F14: =DataExtract!E14-DataExtract!E13 -> 0 | G14: =(DataExtract!K14+DataExtract!P14)-(DataExtract!K13+DataExtract!P13) -> 660788 | H14: =(DataExtract!L14+DataExtract!Q14)-(DataExtract!L13+DataExtract!Q13) -> 22530 | I14: =(DataExtract!M14+DataExtract!R14)-(DataExtract!M13+DataExtract!R13) -> 0 | J14: =(DataExtract!N14+DataExtract!S14)-(DataExtract!N13+DataExtract!S13) -> 0 | K14: =(DataExtract!O14+DataExtract!T14)-(DataExtract!O13+DataExtract!T13) -> 0 | L14: =DataExtract!U14-DataExtract!U13 -> 0 | M14: =DataExtract!V14-DataExtract!V13 -> 0 | N14: =DataExtract!W14-DataExtract!W13 -> 0 | O14: =DataExtract!X14-DataExtract!X13 -> 0 | P14: =DataExtract!Y14-DataExtract!Y13 -> 0 | Q14: =G14/SUM($G14:$K14) -> 0.96702853 | R14: =H14/SUM($G14:$K14) -> 0.032971472 | S14: =I14/SUM($G14:$K14) -> 0 | T14: =J14/SUM($G14:$K14) -> 0 | U14: =K14/SUM($G14:$K14) -> 0 | V14: 0 | W14: 0 | X14: 0 | Y14: 0 | Z14: 0
A15: 44347 | B15: =A15-A14 -> 7 | C15: =DataExtract!B15-DataExtract!B14 -> 640546 | D15: =DataExtract!C15-DataExtract!C14 -> 495368 | E15: =DataExtract!D15-DataExtract!D14 -> 145178 | F15: =DataExtract!E15-DataExtract!E14 -> 0 | G15: =(DataExtract!K15+DataExtract!P15)-(DataExtract!K14+DataExtract!P14) -> 640546 | H15: =(DataExtract!L15+DataExtract!Q15)-(DataExtract!L14+DataExtract!Q14) -> 0 | I15: =(DataExtract!M15+DataExtract!R15)-(DataExtract!M14+DataExtract!R14) -> 0 | J15: =(DataExtract!N15+DataExtract!S15)-(DataExtract!N14+DataExtract!S14) -> 0 | K15: =(DataExtract!O15+DataExtract!T15)-(DataExtract!O14+DataExtract!T14) -> 0 | L15: =DataExtract!U15-DataExtract!U14 -> 0 | M15: =DataExtract!V15-DataExtract!V14 -> 0 | N15: =DataExtract!W15-DataExtract!W14 -> 0 | O15: =DataExtract!X15-DataExtract!X14 -> 0 | P15: =DataExtract!Y15-DataExtract!Y14 -> 0 | Q15: =G15/SUM($G15:$K15) -> 1 | R15: =H15/SUM($G15:$K15) -> 0 | S15: =I15/SUM($G15:$K15) -> 0 | T15: =J15/SUM($G15:$K15) -> 0 | U15: =K15/SUM($G15:$K15) -> 0 | V15: 0 | W15: 0 | X15: 0 | Y15: 0 | Z15: 0
A16: 44354 | B16: =A16-A15 -> 7 | C16: =DataExtract!B16-DataExtract!B15 -> 970082 | D16: =DataExtract!C16-DataExtract!C15 -> 704422 | E16: =DataExtract!D16-DataExtract!D15 -> 265660 | F16: =DataExtract!E16-DataExtract!E15 -> 0 | G16: =(DataExtract!K16+DataExtract!P16)-(DataExtract!K15+DataExtract!P15) -> 606272 | H16: =(DataExtract!L16+DataExtract!Q16)-(DataExtract!L15+DataExtract!Q15) -> 363810 | I16: =(DataExtract!M16+DataExtract!R16)-(DataExtract!M15+DataExtract!R15) -> 0 | J16: =(DataExtract!N16+DataExtract!S16)-(DataExtract!N15+DataExtract!S15) -> 0 | K16: =(DataExtract!O16+DataExtract!T16)-(DataExtract!O15+DataExtract!T15) -> 0 | L16: =DataExtract!U16-DataExtract!U15 -> 0 | M16: =DataExtract!V16-DataExtract!V15 -> 0 | N16: =DataExtract!W16-DataExtract!W15 -> 0 | O16: =DataExtract!X16-DataExtract!X15 -> 0 | P16: =DataExtract!Y16-DataExtract!Y15 -> 0 | Q16: =G16/SUM($G16:$K16) -> 0.62496985 | R16: =H16/SUM($G16:$K16) -> 0.37503015 | S16: =I16/SUM($G16:$K16) -> 0 | T16: =J16/SUM($G16:$K16) -> 0 | U16: =K16/SUM($G16:$K16) -> 0 | V16: 0 | W16: 0 | X16: 0 | Y16: 0 | Z16: 0
A17: 44361 | B17: =A17-A16 -> 7 | C17: =DataExtract!B17-DataExtract!B16 -> 1876243 | D17: =DataExtract!C17-DataExtract!C16 -> 1518150 | E17: =DataExtract!D17-DataExtract!D16 -> 358093 | F17: =DataExtract!E17-DataExtract!E16 -> 0 | G17: =(DataExtract!K17+DataExtract!P17)-(DataExtract!K16+DataExtract!P16) -> 662009 | H17: =(DataExtract!L17+DataExtract!Q17)-(DataExtract!L16+DataExtract!Q16) -> 1214234 | I17: =(DataExtract!M17+DataExtract!R17)-(DataExtract!M16+DataExtract!R16) -> 0 | J17: =(DataExtract!N17+DataExtract!S17)-(DataExtract!N16+DataExtract!S16) -> 0 | K17: =(DataExtract!O17+DataExtract!T17)-(DataExtract!O16+DataExtract!T16) -> 0 | L17: =DataExtract!U17-DataExtract!U16 -> 0 | M17: =DataExtract!V17-DataExtract!V16 -> 0 | N17: =DataExtract!W17-DataExtract!W16 -> 0 | O17: =DataExtract!X17-DataExtract!X16 -> 0 | P17: =DataExtract!Y17-DataExtract!Y16 -> 0 | Q17: =G17/SUM($G17:$K17) -> 0.35283756 | R17: =H17/SUM($G17:$K17) -> 0.64716244 | S17: =I17/SUM($G17:$K17) -> 0 | T17: =J17/SUM($G17:$K17) -> 0 | U17: =K17/SUM($G17:$K17) -> 0 | V17: 0 | W17: 0 | X17: 0 | Y17: 0 | Z17: 0
A18: 44368 | B18: =A18-A17 -> 7 | C18: =DataExtract!B18-DataExtract!B17 -> 1395512 | D18: =DataExtract!C18-DataExtract!C17 -> 916785 | E18: =DataExtract!D18-DataExtract!D17 -> 478727 | F18: =DataExtract!E18-DataExtract!E17 -> 0 | G18: =(DataExtract!K18+DataExtract!P18)-(DataExtract!K17+DataExtract!P17) -> 749401 | H18: =(DataExtract!L18+DataExtract!Q18)-(DataExtract!L17+DataExtract!Q17) -> 646111 | I18: =(DataExtract!M18+DataExtract!R18)-(DataExtract!M17+DataExtract!R17) -> 0 | J18: =(DataExtract!N18+DataExtract!S18)-(DataExtract!N17+DataExtract!S17) -> 0 | K18: =(DataExtract!O18+DataExtract!T18)-(DataExtract!O17+DataExtract!T17) -> 0 | L18: =DataExtract!U18-DataExtract!U17 -> 0 | M18: =DataExtract!V18-DataExtract!V17 -> 0 | N18: =DataExtract!W18-DataExtract!W17 -> 0 | O18: =DataExtract!X18-DataExtract!X17 -> 0 | P18: =DataExtract!Y18-DataExtract!Y17 -> 0 | Q18: =G18/SUM($G18:$K18) -> 0.53700792 | R18: =H18/SUM($G18:$K18) -> 0.46299208 | S18: =I18/SUM($G18:$K18) -> 0 | T18: =J18/SUM($G18:$K18) -> 0 | U18: =K18/SUM($G18:$K18) -> 0 | V18: 0 | W18: 0 | X18: 0 | Y18: 0 | Z18: 0
A19: 44375 | B19: =A19-A18 -> 7 | C19: =DataExtract!B19-DataExtract!B18 -> 1510276 | D19: =DataExtract!C19-DataExtract!C18 -> 1042190 | E19: =DataExtract!D19-DataExtract!D18 -> 468086 | F19: =DataExtract!E19-DataExtract!E18 -> 0 | G19: =(DataExtract!K19+DataExtract!P19)-(DataExtract!K18+DataExtract!P18) -> 611241 | H19: =(DataExtract!L19+DataExtract!Q19)-(DataExtract!L18+DataExtract!Q18) -> 887582 | I19: =(DataExtract!M19+DataExtract!R19)-(DataExtract!M18+DataExtract!R18) -> 11453 | J19: =(DataExtract!N19+DataExtract!S19)-(DataExtract!N18+DataExtract!S18) -> 0 | K19: =(DataExtract!O19+DataExtract!T19)-(DataExtract!O18+DataExtract!T18) -> 0 | L19: =DataExtract!U19-DataExtract!U18 -> 0 | M19: =DataExtract!V19-DataExtract!V18 -> 0 | N19: =DataExtract!W19-DataExtract!W18 -> 0 | O19: =DataExtract!X19-DataExtract!X18 -> 0 | P19: =DataExtract!Y19-DataExtract!Y18 -> 0 | Q19: =G19/SUM($G19:$K19) -> 0.40472139 | R19: =H19/SUM($G19:$K19) -> 0.58769523 | S19: =I19/SUM($G19:$K19) -> 0.0075833821 | T19: =J19/SUM($G19:$K19) -> 0 | U19: =K19/SUM($G19:$K19) -> 0 | V19: 0 | W19: 0 | X19: 0 | Y19: 0 | Z19: 0
A20: 44382 | B20: =A20-A19 -> 7 | C20: =DataExtract!B20-DataExtract!B19 -> 1641418 | D20: =DataExtract!C20-DataExtract!C19 -> 1300991 | E20: =DataExtract!D20-DataExtract!D19 -> 340427 | F20: =DataExtract!E20-DataExtract!E19 -> 0 | G20: =(DataExtract!K20+DataExtract!P20)-(DataExtract!K19+DataExtract!P19) -> 456877 | H20: =(DataExtract!L20+DataExtract!Q20)-(DataExtract!L19+DataExtract!Q19) -> 1063493 | I20: =(DataExtract!M20+DataExtract!R20)-(DataExtract!M19+DataExtract!R19) -> 121048 | J20: =(DataExtract!N20+DataExtract!S20)-(DataExtract!N19+DataExtract!S19) -> 0 | K20: =(DataExtract!O20+DataExtract!T20)-(DataExtract!O19+DataExtract!T19) -> 0 | L20: =DataExtract!U20-DataExtract!U19 -> 0 | M20: =DataExtract!V20-DataExtract!V19 -> 0 | N20: =DataExtract!W20-DataExtract!W19 -> 0 | O20: =DataExtract!X20-DataExtract!X19 -> 0 | P20: =DataExtract!Y20-DataExtract!Y19 -> 0 | Q20: =G20/SUM($G20:$K20) -> 0.27834287 | R20: =H20/SUM($G20:$K20) -> 0.64791114 | S20: =I20/SUM($G20:$K20) -> 0.073745993 | T20: =J20/SUM($G20:$K20) -> 0 | U20: =K20/SUM($G20:$K20) -> 0 | V20: 0 | W20: 0 | X20: 0 | Y20: 0 | Z20: 0
A21: 44389 | B21: =A21-A20 -> 7 | C21: =DataExtract!B21-DataExtract!B20 -> 1849803 | D21: =DataExtract!C21-DataExtract!C20 -> 1576920 | E21: =DataExtract!D21-DataExtract!D20 -> 272883 | F21: =DataExtract!E21-DataExtract!E20 -> 0 | G21: =(DataExtract!K21+DataExtract!P21)-(DataExtract!K20+DataExtract!P20) -> 465904 | H21: =(DataExtract!L21+DataExtract!Q21)-(DataExtract!L20+DataExtract!Q20) -> 1255789 | I21: =(DataExtract!M21+DataExtract!R21)-(DataExtract!M20+DataExtract!R20) -> 128110 | J21: =(DataExtract!N21+DataExtract!S21)-(DataExtract!N20+DataExtract!S20) -> 0 | K21: =(DataExtract!O21+DataExtract!T21)-(DataExtract!O20+DataExtract!T20) -> 0 | L21: =DataExtract!U21-DataExtract!U20 -> 0 | M21: =DataExtract!V21-DataExtract!V20 -> 0 | N21: =DataExtract!W21-DataExtract!W20 -> 0 | O21: =DataExtract!X21-DataExtract!X20 -> 0 | P21: =DataExtract!Y21-DataExtract!Y20 -> 0 | Q21: =G21/SUM($G21:$K21) -> 0.25186682 | R21: =H21/SUM($G21:$K21) -> 0.67887716 | S21: =I21/SUM($G21:$K21) -> 0.069256023 | T21: =J21/SUM($G21:$K21) -> 0 | U21: =K21/SUM($G21:$K21) -> 0 | V21: 0 | W21: 0 | X21: 0 | Y21: 0 | Z21: 0
A22: 44396 | B22: =A22-A21 -> 7 | C22: =DataExtract!B22-DataExtract!B21 -> 1639051 | D22: =DataExtract!C22-DataExtract!C21 -> 1468569 | E22: =DataExtract!D22-DataExtract!D21 -> 170482 | F22: =DataExtract!E22-DataExtract!E21 -> 0 | G22: =(DataExtract!K22+DataExtract!P22)-(DataExtract!K21+DataExtract!P21) -> 523399 | H22: =(DataExtract!L22+DataExtract!Q22)-(DataExtract!L21+DataExtract!Q21) -> 901071 | I22: =(DataExtract!M22+DataExtract!R22)-(DataExtract!M21+DataExtract!R21) -> 214581 | J22: =(DataExtract!N22+DataExtract!S22)-(DataExtract!N21+DataExtract!S21) -> 0 | K22: =(DataExtract!O22+DataExtract!T22)-(DataExtract!O21+DataExtract!T21) -> 0 | L22: =DataExtract!U22-DataExtract!U21 -> 0 | M22: =DataExtract!V22-DataExtract!V21 -> 0 | N22: =DataExtract!W22-DataExtract!W21 -> 0 | O22: =DataExtract!X22-DataExtract!X21 -> 0 | P22: =DataExtract!Y22-DataExtract!Y21 -> 0 | Q22: =G22/SUM($G22:$K22) -> 0.31933052 | R22: =H22/SUM($G22:$K22) -> 0.54975166 | S22: =I22/SUM($G22:$K22) -> 0.13091783 | T22: =J22/SUM($G22:$K22) -> 0 | U22: =K22/SUM($G22:$K22) -> 0 | V22: 0 | W22: 0 | X22: 0 | Y22: 0 | Z22: 0
A23: 44402 | B23: =A23-A22 -> 6 | C23: =DataExtract!B23-DataExtract!B22 -> 1413534 | D23: =DataExtract!C23-DataExtract!C22 -> 1240270 | E23: =DataExtract!D23-DataExtract!D22 -> 173264 | F23: =DataExtract!E23-DataExtract!E22 -> 0 | G23: =(DataExtract!K23+DataExtract!P23)-(DataExtract!K22+DataExtract!P22) -> 508325 | H23: =(DataExtract!L23+DataExtract!Q23)-(DataExtract!L22+DataExtract!Q22) -> 675286 | I23: =(DataExtract!M23+DataExtract!R23)-(DataExtract!M22+DataExtract!R22) -> 229923 | J23: =(DataExtract!N23+DataExtract!S23)-(DataExtract!N22+DataExtract!S22) -> 0 | K23: =(DataExtract!O23+DataExtract!T23)-(DataExtract!O22+DataExtract!T22) -> 0 | L23: =DataExtract!U23-DataExtract!U22 -> 0 | M23: =DataExtract!V23-DataExtract!V22 -> 0 | N23: =DataExtract!W23-DataExtract!W22 -> 0 | O23: =DataExtract!X23-DataExtract!X22 -> 0 | P23: =DataExtract!Y23-DataExtract!Y22 -> 0 | Q23: =G23/SUM($G23:$K23) -> 0.35961286 | R23: =H23/SUM($G23:$K23) -> 0.47772887 | S23: =I23/SUM($G23:$K23) -> 0.16265827 | T23: =J23/SUM($G23:$K23) -> 0 | U23: =K23/SUM($G23:$K23) -> 0 | V23: 0 | W23: 0 | X23: 0 | Y23: 0 | Z23: 0
A24: 44410 | B24: =A24-A23 -> 8 | C24: =DataExtract!B24-DataExtract!B23 -> 2238047 | D24: =DataExtract!C24-DataExtract!C23 -> 1899689 | E24: =DataExtract!D24-DataExtract!D23 -> 338358 | F24: =DataExtract!E24-DataExtract!E23 -> 0 | G24: =(DataExtract!K24+DataExtract!P24)-(DataExtract!K23+DataExtract!P23) -> 745191 | H24: =(DataExtract!L24+DataExtract!Q24)-(DataExtract!L23+DataExtract!Q23) -> 1089095 | I24: =(DataExtract!M24+DataExtract!R24)-(DataExtract!M23+DataExtract!R23) -> 403761 | J24: =(DataExtract!N24+DataExtract!S24)-(DataExtract!N23+DataExtract!S23) -> 0 | K24: =(DataExtract!O24+DataExtract!T24)-(DataExtract!O23+DataExtract!T23) -> 0 | L24: =DataExtract!U24-DataExtract!U23 -> 0 | M24: =DataExtract!V24-DataExtract!V23 -> 0 | N24: =DataExtract!W24-DataExtract!W23 -> 0 | O24: =DataExtract!X24-DataExtract!X23 -> 0 | P24: =DataExtract!Y24-DataExtract!Y23 -> 0 | Q24: =G24/SUM($G24:$K24) -> 0.33296486 | R24: =H24/SUM($G24:$K24) -> 0.4866274 | S24: =I24/SUM($G24:$K24) -> 0.18040774 | T24: =J24/SUM($G24:$K24) -> 0 | U24: =K24/SUM($G24:$K24) -> 0 | V24: 0 | W24: 0 | X24: 0 | Y24: 0 | Z24: 0
A25: 44417 | B25: =A25-A24 -> 7 | C25: =DataExtract!B25-DataExtract!B24 -> 2972285 | D25: =DataExtract!C25-DataExtract!C24 -> 2129266 | E25: =DataExtract!D25-DataExtract!D24 -> 574997 | F25: =DataExtract!E25-DataExtract!E24 -> 268022 | G25: =(DataExtract!K25+DataExtract!P25)-(DataExtract!K24+DataExtract!P24) -> 1407307 | H25: =(DataExtract!L25+DataExtract!Q25)-(DataExtract!L24+DataExtract!Q24) -> 817267 | I25: =(DataExtract!M25+DataExtract!R25)-(DataExtract!M24+DataExtract!R24) -> 432848 | J25: =(DataExtract!N25+DataExtract!S25)-(DataExtract!N24+DataExtract!S24) -> 46841 | K25: =(DataExtract!O25+DataExtract!T25)-(DataExtract!O24+DataExtract!T24) -> 0 | L25: =DataExtract!U25-DataExtract!U24 -> 0 | M25: =DataExtract!V25-DataExtract!V24 -> 185029 | N25: =DataExtract!W25-DataExtract!W24 -> 0 | O25: =DataExtract!X25-DataExtract!X24 -> 82993 | P25: =DataExtract!Y25-DataExtract!Y24 -> 0 | Q25: =G25/SUM($G25:$K25) -> 0.52040316 | R25: =H25/SUM($G25:$K25) -> 0.30221432 | S25: =I25/SUM($G25:$K25) -> 0.16006135 | T25: =J25/SUM($G25:$K25) -> 0.01732117 | U25: =K25/SUM($G25:$K25) -> 0 | V25: =L25/SUM($L25:$P25) -> 0 | W25: =M25/SUM($L25:$P25) -> 0.69035005 | X25: =N25/SUM($L25:$P25) -> 0 | Y25: =O25/SUM($L25:$P25) -> 0.30964995 | Z25: =P25/SUM($L25:$P25) -> 0
A26: 44424 | B26: =A26-A25 -> 7 | C26: =DataExtract!B26-DataExtract!B25 -> 2929521 | D26: =DataExtract!C26-DataExtract!C25 -> 2034254 | E26: =DataExtract!D26-DataExtract!D25 -> 661812 | F26: =DataExtract!E26-DataExtract!E25 -> 233455 | G26: =(DataExtract!K26+DataExtract!P26)-(DataExtract!K25+DataExtract!P25) -> 1130318 | H26: =(DataExtract!L26+DataExtract!Q26)-(DataExtract!L25+DataExtract!Q25) -> 1012395 | I26: =(DataExtract!M26+DataExtract!R26)-(DataExtract!M25+DataExtract!R25) -> 495094 | J26: =(DataExtract!N26+DataExtract!S26)-(DataExtract!N25+DataExtract!S25) -> 58259 | K26: =(DataExtract!O26+DataExtract!T26)-(DataExtract!O25+DataExtract!T25) -> 0 | L26: =DataExtract!U26-DataExtract!U25 -> 0 | M26: =DataExtract!V26-DataExtract!V25 -> 12482 | N26: =DataExtract!W26-DataExtract!W25 -> 0 | O26: =DataExtract!X26-DataExtract!X25 -> 220973 | P26: =DataExtract!Y26-DataExtract!Y25 -> 0 | Q26: =G26/SUM($G26:$K26) -> 0.41924715 | R26: =H26/SUM($G26:$K26) -> 0.37550824 | S26: =I26/SUM($G26:$K26) -> 0.18363571 | T26: =J26/SUM($G26:$K26) -> 0.021608892 | U26: =K26/SUM($G26:$K26) -> 0 | V26: =L26/SUM($L26:$P26) -> 0 | W26: =M26/SUM($L26:$P26) -> 0.053466407 | X26: =N26/SUM($L26:$P26) -> 0 | Y26: =O26/SUM($L26:$P26) -> 0.94653359 | Z26: =P26/SUM($L26:$P26) -> 0
A27: 44431 | B27: =A27-A26 -> 7 | C27: =DataExtract!B27-DataExtract!B26 -> 3511814 | D27: =DataExtract!C27-DataExtract!C26 -> 2459676 | E27: =DataExtract!D27-DataExtract!D26 -> 1002354 | F27: =DataExtract!E27-DataExtract!E26 -> 49784 | G27: =(DataExtract!K27+DataExtract!P27)-(DataExtract!K26+DataExtract!P26) -> 1375369 | H27: =(DataExtract!L27+DataExtract!Q27)-(DataExtract!L26+DataExtract!Q26) -> 1290098 | I27: =(DataExtract!M27+DataExtract!R27)-(DataExtract!M26+DataExtract!R26) -> 687032 | J27: =(DataExtract!N27+DataExtract!S27)-(DataExtract!N26+DataExtract!S26) -> 109531 | K27: =(DataExtract!O27+DataExtract!T27)-(DataExtract!O26+DataExtract!T26) -> 0 | L27: =DataExtract!U27-DataExtract!U26 -> 0 | M27: =DataExtract!V27-DataExtract!V26 -> 6617 | N27: =DataExtract!W27-DataExtract!W26 -> 0 | O27: =DataExtract!X27-DataExtract!X26 -> 43167 | P27: =DataExtract!Y27-DataExtract!Y26 -> 0 | Q27: =G27/SUM($G27:$K27) -> 0.39727241 | R27: =H27/SUM($G27:$K27) -> 0.37264206 | S27: =I27/SUM($G27:$K27) -> 0.19844773 | T27: =J27/SUM($G27:$K27) -> 0.031637796 | U27: =K27/SUM($G27:$K27) -> 0 | V27: =L27/SUM($L27:$P27) -> 0 | W27: =M27/SUM($L27:$P27) -> 0.13291419 | X27: =N27/SUM($L27:$P27) -> 0 | Y27: =O27/SUM($L27:$P27) -> 0.86708581 | Z27: =P27/SUM($L27:$P27) -> 0
A28: 44438 | B28: =A28-A27 -> 7 | C28: =DataExtract!B28-DataExtract!B27 -> 4159374 | D28: =DataExtract!C28-DataExtract!C27 -> 2570792 | E28: =DataExtract!D28-DataExtract!D27 -> 1550462 | F28: =DataExtract!E28-DataExtract!E27 -> 38120 | G28: =(DataExtract!K28+DataExtract!P28)-(DataExtract!K27+DataExtract!P27) -> 1453487 | H28: =(DataExtract!L28+DataExtract!Q28)-(DataExtract!L27+DataExtract!Q27) -> 1677718 | I28: =(DataExtract!M28+DataExtract!R28)-(DataExtract!M27+DataExtract!R27) -> 827603 | J28: =(DataExtract!N28+DataExtract!S28)-(DataExtract!N27+DataExtract!S27) -> 162446 | K28: =(DataExtract!O28+DataExtract!T28)-(DataExtract!O27+DataExtract!T27) -> 0 | L28: =DataExtract!U28-DataExtract!U27 -> 0 | M28: =DataExtract!V28-DataExtract!V27 -> 5027 | N28: =DataExtract!W28-DataExtract!W27 -> 0 | O28: =DataExtract!X28-DataExtract!X27 -> 33093 | P28: =DataExtract!Y28-DataExtract!Y27 -> 0 | Q28: =G28/SUM($G28:$K28) -> 0.35268076 | R28: =H28/SUM($G28:$K28) -> 0.4070892 | S28: =I28/SUM($G28:$K28) -> 0.20081339 | T28: =J28/SUM($G28:$K28) -> 0.039416644 | U28: =K28/SUM($G28:$K28) -> 0 | V28: =L28/SUM($L28:$P28) -> 0 | W28: =M28/SUM($L28:$P28) -> 0.13187303 | X28: =N28/SUM($L28:$P28) -> 0 | Y28: =O28/SUM($L28:$P28) -> 0.86812697 | Z28: =P28/SUM($L28:$P28) -> 0
A29: 44445 | B29: =A29-A28 -> 7 | C29: =DataExtract!B29-DataExtract!B28 -> 4863452 | D29: =DataExtract!C29-DataExtract!C28 -> 2152991 | E29: =DataExtract!D29-DataExtract!D28 -> 2694352 | F29: =DataExtract!E29-DataExtract!E28 -> 16109 | G29: =(DataExtract!K29+DataExtract!P29)-(DataExtract!K28+DataExtract!P28) -> 1274515 | H29: =(DataExtract!L29+DataExtract!Q29)-(DataExtract!L28+DataExtract!Q28) -> 2538151 | I29: =(DataExtract!M29+DataExtract!R29)-(DataExtract!M28+DataExtract!R28) -> 910850 | J29: =(DataExtract!N29+DataExtract!S29)-(DataExtract!N28+DataExtract!S28) -> 123827 | K29: =(DataExtract!O29+DataExtract!T29)-(DataExtract!O28+DataExtract!T28) -> 0 | L29: =DataExtract!U29-DataExtract!U28 -> 0 | M29: =DataExtract!V29-DataExtract!V28 -> 3540 | N29: =DataExtract!W29-DataExtract!W28 -> 0 | O29: =DataExtract!X29-DataExtract!X28 -> 12569 | P29: =DataExtract!Y29-DataExtract!Y28 -> 0 | Q29: =G29/SUM($G29:$K29) -> 0.26293064 | R29: =H29/SUM($G29:$K29) -> 0.52361696 | S29: =I29/SUM($G29:$K29) -> 0.18790707 | T29: =J29/SUM($G29:$K29) -> 0.025545335 | U29: =K29/SUM($G29:$K29) -> 0 | V29: =L29/SUM($L29:$P29) -> 0 | W29: =M29/SUM($L29:$P29) -> 0.21975293 | X29: =N29/SUM($L29:$P29) -> 0 | Y29: =O29/SUM($L29:$P29) -> 0.78024707 | Z29: =P29/SUM($L29:$P29) -> 0
A30: 44452 | B30: =A30-A29 -> 7 | C30: =DataExtract!B30-DataExtract!B29 -> 4317754 | D30: =DataExtract!C30-DataExtract!C29 -> 1986287 | E30: =DataExtract!D30-DataExtract!D29 -> 2320382 | F30: =DataExtract!E30-DataExtract!E29 -> 11085 | G30: =(DataExtract!K30+DataExtract!P30)-(DataExtract!K29+DataExtract!P29) -> 1300952 | H30: =(DataExtract!L30+DataExtract!Q30)-(DataExtract!L29+DataExtract!Q29) -> 1912713 | I30: =(DataExtract!M30+DataExtract!R30)-(DataExtract!M29+DataExtract!R29) -> 933238 | J30: =(DataExtract!N30+DataExtract!S30)-(DataExtract!N29+DataExtract!S29) -> 159766 | K30: =(DataExtract!O30+DataExtract!T30)-(DataExtract!O29+DataExtract!T29) -> 0 | L30: =DataExtract!U30-DataExtract!U29 -> 0 | M30: =DataExtract!V30-DataExtract!V29 -> 4558 | N30: =DataExtract!W30-DataExtract!W29 -> 0 | O30: =DataExtract!X30-DataExtract!X29 -> 6527 | P30: =DataExtract!Y30-DataExtract!Y29 -> 0 | Q30: =G30/SUM($G30:$K30) -> 0.30207847 | R30: =H30/SUM($G30:$K30) -> 0.44412816 | S30: =I30/SUM($G30:$K30) -> 0.21669601 | T30: =J30/SUM($G30:$K30) -> 0.037097348 | U30: =K30/SUM($G30:$K30) -> 0 | V30: =L30/SUM($L30:$P30) -> 0 | W30: =M30/SUM($L30:$P30) -> 0.41118629 | X30: =N30/SUM($L30:$P30) -> 0 | Y30: =O30/SUM($L30:$P30) -> 0.58881371 | Z30: =P30/SUM($L30:$P30) -> 0
A31: 44459 | B31: =A31-A30 -> 7 | C31: =DataExtract!B31-DataExtract!B30 -> 4258076 | D31: =DataExtract!C31-DataExtract!C30 -> 1660334 | E31: =DataExtract!D31-DataExtract!D30 -> 2592364 | F31: =DataExtract!E31-DataExtract!E30 -> 5378 | G31: =(DataExtract!K31+DataExtract!P31)-(DataExtract!K30+DataExtract!P30) -> 1015919 | H31: =(DataExtract!L31+DataExtract!Q31)-(DataExtract!L30+DataExtract!Q30) -> 1968426 | I31: =(DataExtract!M31+DataExtract!R31)-(DataExtract!M30+DataExtract!R30) -> 1094714 | J31: =(DataExtract!N31+DataExtract!S31)-(DataExtract!N30+DataExtract!S30) -> 173639 | K31: =(DataExtract!O31+DataExtract!T31)-(DataExtract!O30+DataExtract!T30) -> 0 | L31: =DataExtract!U31-DataExtract!U30 -> 0 | M31: =DataExtract!V31-DataExtract!V30 -> 1958 | N31: =DataExtract!W31-DataExtract!W30 -> 0 | O31: =DataExtract!X31-DataExtract!X30 -> 3420 | P31: =DataExtract!Y31-DataExtract!Y30 -> 0 | Q31: =G31/SUM($G31:$K31) -> 0.23888811 | R31: =H31/SUM($G31:$K31) -> 0.46286522 | S31: =I31/SUM($G31:$K31) -> 0.25741635 | T31: =J31/SUM($G31:$K31) -> 0.040830315 | U31: =K31/SUM($G31:$K31) -> 0 | V31: =L31/SUM($L31:$P31) -> 0 | W31: =M31/SUM($L31:$P31) -> 0.36407586 | X31: =N31/SUM($L31:$P31) -> 0 | Y31: =O31/SUM($L31:$P31) -> 0.63592414 | Z31: =P31/SUM($L31:$P31) -> 0
A32: 44473 | B32: =A32-A31 -> 14 | C32: =DataExtract!B32-DataExtract!B31 -> 10710342 | D32: =DataExtract!C32-DataExtract!C31 -> 4042448 | E32: =DataExtract!D32-DataExtract!D31 -> 5774180 | F32: =DataExtract!E32-DataExtract!E31 -> 893714 | G32: =(DataExtract!K32+DataExtract!P32)-(DataExtract!K31+DataExtract!P31) -> 2455336 | H32: =(DataExtract!L32+DataExtract!Q32)-(DataExtract!L31+DataExtract!Q31) -> 4715606 | I32: =(DataExtract!M32+DataExtract!R32)-(DataExtract!M31+DataExtract!R31) -> 2503657 | J32: =(DataExtract!N32+DataExtract!S32)-(DataExtract!N31+DataExtract!S31) -> 142029 | K32: =(DataExtract!O32+DataExtract!T32)-(DataExtract!O31+DataExtract!T31) -> 0 | L32: =DataExtract!U32-DataExtract!U31 -> 0 | M32: =DataExtract!V32-DataExtract!V31 -> 810175 | N32: =DataExtract!W32-DataExtract!W31 -> 0 | O32: =DataExtract!X32-DataExtract!X31 -> 83539 | P32: =DataExtract!Y32-DataExtract!Y31 -> 0 | Q32: =G32/SUM($G32:$K32) -> 0.2501201 | R32: =H32/SUM($G32:$K32) -> 0.48036923 | S32: =I32/SUM($G32:$K32) -> 0.25504246 | T32: =J32/SUM($G32:$K32) -> 0.014468206 | U32: =K32/SUM($G32:$K32) -> 0 | V32: =L32/SUM($L32:$P32) -> 0 | W32: =M32/SUM($L32:$P32) -> 0.90652603 | X32: =N32/SUM($L32:$P32) -> 0 | Y32: =O32/SUM($L32:$P32) -> 0.093473975 | Z32: =P32/SUM($L32:$P32) -> 0
A33: 44480 | B33: =A33-A32 -> 7 | C33: =DataExtract!B33-DataExtract!B32 -> 5111808 | D33: =DataExtract!C33-DataExtract!C32 -> 2218645 | E33: =DataExtract!D33-DataExtract!D32 -> 2634246 | F33: =DataExtract!E33-DataExtract!E32 -> 258917 | G33: =(DataExtract!K33+DataExtract!P33)-(DataExtract!K32+DataExtract!P32) -> 902828 | H33: =(DataExtract!L33+DataExtract!Q33)-(DataExtract!L32+DataExtract!Q32) -> 2049735 | I33: =(DataExtract!M33+DataExtract!R33)-(DataExtract!M32+DataExtract!R32) -> 1029723 | J33: =(DataExtract!N33+DataExtract!S33)-(DataExtract!N32+DataExtract!S32) -> 870605 | K33: =(DataExtract!O33+DataExtract!T33)-(DataExtract!O32+DataExtract!T32) -> 0 | L33: =DataExtract!U33-DataExtract!U32 -> 0 | M33: =DataExtract!V33-DataExtract!V32 -> 253319 | N33: =DataExtract!W33-DataExtract!W32 -> 0 | O33: =DataExtract!X33-DataExtract!X32 -> 5598 | P33: =DataExtract!Y33-DataExtract!Y32 -> 0 | Q33: =G33/SUM($G33:$K33) -> 0.18603921 | R33: =H33/SUM($G33:$K33) -> 0.422374 | S33: =I33/SUM($G33:$K33) -> 0.21218754 | T33: =J33/SUM($G33:$K33) -> 0.17939925 | U33: =K33/SUM($G33:$K33) -> 0 | V33: =L33/SUM($L33:$P33) -> 0 | W33: =M33/SUM($L33:$P33) -> 0.97837917 | X33: =N33/SUM($L33:$P33) -> 0 | Y33: =O33/SUM($L33:$P33) -> 0.021620828 | Z33: =P33/SUM($L33:$P33) -> 0
A34: 44487 | B34: =A34-A33 -> 7 | C34: =DataExtract!B34-DataExtract!B33 -> 5559070 | D34: =DataExtract!C34-DataExtract!C33 -> 2674926 | E34: =DataExtract!D34-DataExtract!D33 -> 2678025 | F34: =DataExtract!E34-DataExtract!E33 -> 206119 | G34: =(DataExtract!K34+DataExtract!P34)-(DataExtract!K33+DataExtract!P33) -> 1089416 | H34: =(DataExtract!L34+DataExtract!Q34)-(DataExtract!L33+DataExtract!Q33) -> 2052603 | I34: =(DataExtract!M34+DataExtract!R34)-(DataExtract!M33+DataExtract!R33) -> 1008061 | J34: =(DataExtract!N34+DataExtract!S34)-(DataExtract!N33+DataExtract!S33) -> 1202871 | K34: =(DataExtract!O34+DataExtract!T34)-(DataExtract!O33+DataExtract!T33) -> 0 | L34: =DataExtract!U34-DataExtract!U33 -> 0 | M34: =DataExtract!V34-DataExtract!V33 -> 201973 | N34: =DataExtract!W34-DataExtract!W33 -> 0 | O34: =DataExtract!X34-DataExtract!X33 -> 4146 | P34: =DataExtract!Y34-DataExtract!Y33 -> 0 | Q34: =G34/SUM($G34:$K34) -> 0.2035169 | R34: =H34/SUM($G34:$K34) -> 0.3834526 | S34: =I34/SUM($G34:$K34) -> 0.18831874 | T34: =J34/SUM($G34:$K34) -> 0.22471175 | U34: =K34/SUM($G34:$K34) -> 0 | V34: =L34/SUM($L34:$P34) -> 0 | W34: =M34/SUM($L34:$P34) -> 0.97988541 | X34: =N34/SUM($L34:$P34) -> 0 | Y34: =O34/SUM($L34:$P34) -> 0.020114594 | Z34: =P34/SUM($L34:$P34) -> 0
A35: 44494 | B35: =A35-A34 -> 7 | C35: =DataExtract!B35-DataExtract!B34 -> 4645199 | D35: =DataExtract!C35-DataExtract!C34 -> 2209185 | E35: =DataExtract!D35-DataExtract!D34 -> 2239382 | F35: =DataExtract!E35-DataExtract!E34 -> 196632 | G35: =(DataExtract!K35+DataExtract!P35)-(DataExtract!K34+DataExtract!P34) -> 980006 | H35: =(DataExtract!L35+DataExtract!Q35)-(DataExtract!L34+DataExtract!Q34) -> 1745967 | I35: =(DataExtract!M35+DataExtract!R35)-(DataExtract!M34+DataExtract!R34) -> 763940 | J35: =(DataExtract!N35+DataExtract!S35)-(DataExtract!N34+DataExtract!S34) -> 958654 | K35: =(DataExtract!O35+DataExtract!T35)-(DataExtract!O34+DataExtract!T34) -> 0 | L35: =DataExtract!U35-DataExtract!U34 -> 0 | M35: =DataExtract!V35-DataExtract!V34 -> 179819 | N35: =DataExtract!W35-DataExtract!W34 -> 0 | O35: =DataExtract!X35-DataExtract!X34 -> 16813 | P35: =DataExtract!Y35-DataExtract!Y34 -> 0 | Q35: =G35/SUM($G35:$K35) -> 0.22029701 | R35: =H35/SUM($G35:$K35) -> 0.39247852 | S35: =I35/SUM($G35:$K35) -> 0.17172721 | T35: =J35/SUM($G35:$K35) -> 0.21549726 | U35: =K35/SUM($G35:$K35) -> 0 | V35: =L35/SUM($L35:$P35) -> 0 | W35: =M35/SUM($L35:$P35) -> 0.9144951 | X35: =N35/SUM($L35:$P35) -> 0 | Y35: =O35/SUM($L35:$P35) -> 0.085504903 | Z35: =P35/SUM($L35:$P35) -> 0
A36: 44501 | B36: =A36-A35 -> 7 | C36: =DataExtract!B36-DataExtract!B35 -> 4988596 | D36: =DataExtract!C36-DataExtract!C35 -> 2202202 | E36: =DataExtract!D36-DataExtract!D35 -> 2530683 | F36: =DataExtract!E36-DataExtract!E35 -> 255711 | G36: =(DataExtract!K36+DataExtract!P36)-(DataExtract!K35+DataExtract!P35) -> 1146328 | H36: =(DataExtract!L36+DataExtract!Q36)-(DataExtract!L35+DataExtract!Q35) -> 1624268 | I36: =(DataExtract!M36+DataExtract!R36)-(DataExtract!M35+DataExtract!R35) -> 614864 | J36: =(DataExtract!N36+DataExtract!S36)-(DataExtract!N35+DataExtract!S35) -> 1347425 | K36: =(DataExtract!O36+DataExtract!T36)-(DataExtract!O35+DataExtract!T35) -> 0 | L36: =DataExtract!U36-DataExtract!U35 -> 0 | M36: =DataExtract!V36-DataExtract!V35 -> 234054 | N36: =DataExtract!W36-DataExtract!W35 -> 0 | O36: =DataExtract!X36-DataExtract!X35 -> 21657 | P36: =DataExtract!Y36-DataExtract!Y35 -> 0 | Q36: =G36/SUM($G36:$K36) -> 0.24220491 | R36: =H36/SUM($G36:$K36) -> 0.34318772 | S36: =I36/SUM($G36:$K36) -> 0.12991315 | T36: =J36/SUM($G36:$K36) -> 0.28469422 | U36: =K36/SUM($G36:$K36) -> 0 | V36: =L36/SUM($L36:$P36) -> 0 | W36: =M36/SUM($L36:$P36) -> 0.91530673 | X36: =N36/SUM($L36:$P36) -> 0 | Y36: =O36/SUM($L36:$P36) -> 0.084693267 | Z36: =P36/SUM($L36:$P36) -> 0
... A52: 44620 | B52: =A52-A51 -> 7 | C52: =DataExtract!B52-DataExtract!B51 -> 1893856 | D52: =DataExtract!C52-DataExtract!C51 -> 414469 | E52: =DataExtract!D52-DataExtract!D51 -> 242135 | F52: =DataExtract!E52-DataExtract!E51 -> 1237252 | G52: =(DataExtract!K52+DataExtract!P52)-(DataExtract!K51+DataExtract!P51) -> 6139 | H52: =(DataExtract!L52+DataExtract!Q52)-(DataExtract!L51+DataExtract!Q51) -> 77525 | I52: =(DataExtract!M52+DataExtract!R52)-(DataExtract!M51+DataExtract!R51) -> 13083 | J52: =(DataExtract!N52+DataExtract!S52)-(DataExtract!N51+DataExtract!S51) -> 524901 | K52: =(DataExtract!O52+DataExtract!T52)-(DataExtract!O51+DataExtract!T51) -> 34956 | L52: =DataExtract!U52-DataExtract!U51 -> 6752 | M52: =DataExtract!V52-DataExtract!V51 -> 162873 | N52: =DataExtract!W52-DataExtract!W51 -> 47046 | O52: =DataExtract!X52-DataExtract!X51 -> 861165 | P52: =DataExtract!Y52-DataExtract!Y51 -> 159416 | Q52: =G52/SUM($G52:$K52) -> 0.0093496232 | R52: =H52/SUM($G52:$K52) -> 0.11806964 | S52: =I52/SUM($G52:$K52) -> 0.019925252 | T52: =J52/SUM($G52:$K52) -> 0.79941791 | U52: =K52/SUM($G52:$K52) -> 0.053237568 | V52: =L52/SUM($L52:$P52) -> 0.0054572553 | W52: =M52/SUM($L52:$P52) -> 0.13164093 | X52: =N52/SUM($L52:$P52) -> 0.03802459 | Y52: =O52/SUM($L52:$P52) -> 0.6960304 | Z52: =P52/SUM($L52:$P52) -> 0.12884683
A53: 44627 | B53: =A53-A52 -> 7 | C53: =DataExtract!B53-DataExtract!B52 -> 1226717 | D53: =DataExtract!C53-DataExtract!C52 -> 405845 | E53: =DataExtract!D53-DataExtract!D52 -> 139373 | F53: =DataExtract!E53-DataExtract!E52 -> 681499 | G53: =(DataExtract!K53+DataExtract!P53)-(DataExtract!K52+DataExtract!P52) -> 4592 | H53: =(DataExtract!L53+DataExtract!Q53)-(DataExtract!L52+DataExtract!Q52) -> 51301 | I53: =(DataExtract!M53+DataExtract!R53)-(DataExtract!M52+DataExtract!R52) -> 11834 | J53: =(DataExtract!N53+DataExtract!S53)-(DataExtract!N52+DataExtract!S52) -> 453527 | K53: =(DataExtract!O53+DataExtract!T53)-(DataExtract!O52+DataExtract!T52) -> 23964 | L53: 0 | M53: =DataExtract!V53-DataExtract!V52 -> 103696 | N53: 0 | O53: =DataExtract!X53-DataExtract!X52 -> 496352 | P53: =DataExtract!Y53-DataExtract!Y52 -> 135249 | Q53: =G53/SUM($G53:$K53) -> 0.0084223191 | R53: =H53/SUM($G53:$K53) -> 0.094092638 | S53: =I53/SUM($G53:$K53) -> 0.021705079 | T53: =J53/SUM($G53:$K53) -> 0.8318269 | U53: =K53/SUM($G53:$K53) -> 0.043953061 | V53: =L53/SUM($L53:$P53) -> 0 | W53: =M53/SUM($L53:$P53) -> 0.14102601 | X53: =N53/SUM($L53:$P53) -> 0 | Y53: =O53/SUM($L53:$P53) -> 0.67503607 | Z53: =P53/SUM($L53:$P53) -> 0.18393792
A54: 44634 | B54: =A54-A53 -> 7 | C54: =DataExtract!B54-DataExtract!B53 -> 1231399 | D54: =DataExtract!C54-DataExtract!C53 -> 469981 | E54: =DataExtract!D54-DataExtract!D53 -> 124470 | F54: =DataExtract!E54-DataExtract!E53 -> 636948 | G54: =(DataExtract!K54+DataExtract!P54)-(DataExtract!K53+DataExtract!P53) -> 5222 | H54: =(DataExtract!L54+DataExtract!Q54)-(DataExtract!L53+DataExtract!Q53) -> 45324 | I54: =(DataExtract!M54+DataExtract!R54)-(DataExtract!M53+DataExtract!R53) -> 8879 | J54: =(DataExtract!N54+DataExtract!S54)-(DataExtract!N53+DataExtract!S53) -> 513957 | K54: =(DataExtract!O54+DataExtract!T54)-(DataExtract!O53+DataExtract!T53) -> 21069 | L54: =DataExtract!U54-DataExtract!U53 -> 0 | M54: =DataExtract!V54-DataExtract!V53 -> 102380 | N54: =DataExtract!W54-DataExtract!W53 -> 0 | O54: =DataExtract!X54-DataExtract!X53 -> 415040 | P54: =DataExtract!Y54-DataExtract!Y53 -> 119528 | Q54: =G54/SUM($G54:$K54) -> 0.008784576 | R54: =H54/SUM($G54:$K54) -> 0.07624514 | S54: =I54/SUM($G54:$K54) -> 0.014936471 | T54: =J54/SUM($G54:$K54) -> 0.86459103 | U54: =K54/SUM($G54:$K54) -> 0.035442787 | V54: =L54/SUM($L54:$P54) -> 0 | W54: =M54/SUM($L54:$P54) -> 0.16073526 | X54: =N54/SUM($L54:$P54) -> 0 | Y54: =O54/SUM($L54:$P54) -> 0.65160735 | Z54: =P54/SUM($L54:$P54) -> 0.18765739
A55: 44641 | B55: =A55-A54 -> 7 | C55: =DataExtract!B55-DataExtract!B54 -> 1220945 | D55: =DataExtract!C55-DataExtract!C54 -> 458908 | E55: =DataExtract!D55-DataExtract!D54 -> 124161 | F55: =DataExtract!E55-DataExtract!E54 -> 637876 | G55: =(DataExtract!K55+DataExtract!P55)-(DataExtract!K54+DataExtract!P54) -> 5401 | H55: =(DataExtract!L55+DataExtract!Q55)-(DataExtract!L54+DataExtract!Q54) -> 45559 | I55: =(DataExtract!M55+DataExtract!R55)-(DataExtract!M54+DataExtract!R54) -> 9614 | J55: =(DataExtract!N55+DataExtract!S55)-(DataExtract!N54+DataExtract!S54) -> 506136 | K55: =(DataExtract!O55+DataExtract!T55)-(DataExtract!O54+DataExtract!T54) -> 16359 | L55: =DataExtract!U55-DataExtract!U54 -> 0 | M55: =DataExtract!V55-DataExtract!V54 -> 105255 | N55: =DataExtract!W55-DataExtract!W54 -> 0 | O55: =DataExtract!X55-DataExtract!X54 -> 428154 | P55: =DataExtract!Y55-DataExtract!Y54 -> 104467 | Q55: =G55/SUM($G55:$K55) -> 0.0092630546 | R55: =H55/SUM($G55:$K55) -> 0.07813655 | S55: =I55/SUM($G55:$K55) -> 0.016488615 | T55: =J55/SUM($G55:$K55) -> 0.86805507 | U55: =K55/SUM($G55:$K55) -> 0.028056714 | V55: =L55/SUM($L55:$P55) -> 0 | W55: =M55/SUM($L55:$P55) -> 0.16500856 | X55: =N55/SUM($L55:$P55) -> 0 | Y55: =O55/SUM($L55:$P55) -> 0.67121823 | Z55: =P55/SUM($L55:$P55) -> 0.16377321
...

Sheet DataExtract
A1: date | B1: total_dose | C1: total_first | D1: total_second | E1: total_boost | F1: total_sv | G1: total_az | H1: total_sp | I1: total_pf | J1: total_moderna | K1: sv_first | L1: az_first | M1: sp_first | N1: pf_first | O1: moderna_first | P1: sv_second | Q1: az_second | R1: sp_second | S1: pf_second | T1: moderna_second | U1: sv_boost | V1: az_boost | W1: sp_boost | X1: pf_boost | Y1: moderna_boost | Z1: CHECK | AE1: age_12_17_first | AF1: age_12_17_second | AG1: age_18_59_first | AH1: age_18_59_second | AI1: age_18_59_third | AJ1: age_60_first | AK1: age_60_second | AL1: age_60_third
A2: 44255 | B2: 0 | C2: 0 | D2: 0 | E2: 0 | Z2: =SUM(C2:E2)=B2 -> TRUE
A3: 44263 | B3: 29900 | C3: 29900 | D3: 0 | E3: 0 | Z3: =SUM(C3:E3)=B3 -> TRUE
A4: 44270 | B4: 50388 | C4: 50388 | D4: 0 | E4: 0 | Z4: =SUM(C4:E4)=B4 -> TRUE
A5: 44277 | B5: 85241 | C5: 82812 | D5: 2429 | E5: 0 | Z5: =SUM(C5:E5)=B5 -> TRUE
A6: 44284 | B6: 166358 | C6: 141081 | D6: 25277 | E6: 0 | F6: =B6-G6 -> 155795 | G6: =10559+4 -> 10563 | H6: 0 | I6: 0 | J6: 0 | K6: =F6 -> 155795 | L6: =G6 -> 10563 | M6: 0 | N6: 0 | O6: 0 | P6: 0 | Q6: 0 | R6: 0 | S6: 0 | T6: 0 | Z6: =SUM(C6:E6)=B6 -> TRUE | AA6: =SUM(F6:J6)=B6 -> TRUE
A7: 44291 | B7: 294881 | C7: 247850 | D7: 47031 | E7: 0 | F7: =205832+47031 -> 252863 | G7: 42018 | H7: 0 | I7: 0 | J7: 0 | K7: 205832 | L7: 42018 | M7: 0 | N7: 0 | O7: 0 | P7: 47031 | Q7: 0 | R7: 0 | S7: 0 | T7: 0 | Z7: =SUM(C7:E7)=B7 -> TRUE | AA7: =SUM(F7:J7)=B7 -> TRUE | AB7: =SUM(K7:O7)=C7 -> TRUE | AC7: =SUM(P7:T7)=D7 -> TRUE
A8: 44298 | B8: 578532 | C8: 505215 | D8: 73317 | E8: 0 | F8: =450939+73317 -> 524256 | G8: 54276 | H8: 0 | I8: 0 | J8: 0 | K8: 450939 | L8: 54276 | M8: 0 | N8: 0 | O8: 0 | P8: 73317 | Q8: 0 | R8: 0 | S8: 0 | T8: 0 | Z8: =SUM(C8:E8)=B8 -> TRUE | AA8: =SUM(F8:J8)=B8 -> TRUE | AB8: =SUM(K8:O8)=C8 -> TRUE | AC8: =SUM(P8:T8)=D8 -> TRUE
A9: 44305 | B9: 666210 | C9: 571825 | D9: 94385 | E9: 0 | F9: =514363+94385 -> 608748 | G9: 57462 | H9: 0 | I9: 0 | J9: 0 | K9: 514363 | L9: 57462 | M9: 0 | N9: 0 | O9: 0 | P9: 94385 | Q9: 0 | R9: 0 | S9: 0 | T9: 0 | Z9: =SUM(C9:E9)=B9 -> TRUE | AA9: =SUM(F9:J9)=B9 -> TRUE | AB9: =SUM(K9:O9)=C9 -> TRUE | AC9: =SUM(P9:T9)=D9 -> TRUE
A10: 44312 | B10: 1227032 | C10: 1012388 | D10: 214644 | E10: 0 | Z10: =SUM(C10:E10)=B10 -> TRUE
A11: 44319 | B11: 1498617 | C11: 1106071 | D11: 392546 | E11: 0 | Z11: =SUM(C11:E11)=B11 -> TRUE
A12: 44326 | B12: 1898454 | C12: 1365992 | D12: 532462 | E12: 0 | Z12: =SUM(C12:E12)=B12 -> TRUE
A13: 44333 | B13: 2340995 | C13: 1521034 | D13: 819961 | E13: 0 | F13: =1414131+817744 -> 2231875 | G13: =106903+2217 -> 109120 | H13: 0 | I13: 0 | J13: 0 | K13: 1414131 | L13: 106903 | M13: 0 | N13: 0 | O13: 0 | P13: 817744 | Q13: 2217 | R13: 0 | S13: 0 | T13: 0 | U13: 0 | V13: 0 | W13: 0 | X13: 0 | Y13: 0 | Z13: =SUM(C13:E13)=B13 -> TRUE | AA13: =SUM(F13:J13)=B13 -> TRUE | AB13: =SUM(K13:O13)=C13 -> TRUE | AC13: =SUM(P13:T13)=D13 -> TRUE
A14: 44340 | B14: 3024313 | C14: 2044123 | D14: 980190 | E14: 0 | F14: =1923847+968816 -> 2892663 | G14: =120276+11374 -> 131650 | H14: 0 | I14: 0 | J14: 0 | K14: 1923847 | L14: 120276 | M14: 0 | N14: 0 | O14: 0 | P14: 968816 | Q14: 11374 | R14: 0 | S14: 0 | T14: 0 | U14: 0 | V14: 0 | W14: 0 | X14: 0 | Y14: 0 | Z14: =SUM(C14:E14)=B14 -> TRUE | AA14: =SUM(F14:J14)=B14 -> TRUE | AB14: =SUM(K14:O14)=C14 -> TRUE | AC14: =SUM(P14:T14)=D14 -> TRUE
A15: 44347 | B15: 3664859 | C15: 2539491 | D15: 1125368 | E15: 0 | F15: =2419215+1113994 -> 3533209 | G15: =120276+11374 -> 131650 | H15: 0 | I15: 0 | J15: 0 | K15: 2419215 | L15: 120276 | M15: 0 | N15: 0 | O15: 0 | P15: 1113994 | Q15: 11374 | R15: 0 | S15: 0 | T15: 0 | U15: 0 | V15: 0 | W15: 0 | X15: 0 | Y15: 0 | Z15: =SUM(C15:E15)=B15 -> TRUE | AA15: =SUM(F15:J15)=B15 -> TRUE | AB15: =SUM(K15:O15)=C15 -> TRUE | AC15: =SUM(P15:T15)=D15 -> TRUE
A16: 44354 | B16: 4634941 | C16: 3243913 | D16: 1391028 | E16: 0 | F16: =2778784+1360697 -> 4139481 | G16: =465129+30331 -> 495460 | H16: 0 | I16: 0 | J16: 0 | K16: 2778784 | L16: 465129 | M16: 0 | N16: 0 | O16: 0 | P16: 1360697 | Q16: 30331 | R16: 0 | S16: 0 | T16: 0 | U16: 0 | V16: 0 | W16: 0 | X16: 0 | Y16: 0 | Z16: =SUM(C16:E16)=B16 -> TRUE | AA16: =SUM(F16:J16)=B16 -> TRUE | AB16: =SUM(K16:O16)=C16 -> TRUE | AC16: =SUM(P16:T16)=D16 -> TRUE
A17: 44361 | B17: 6511184 | C17: 4762063 | D17: 1749121 | E17: 0 | F17: 4801490 | G17: 1709694 | H17: 0 | I17: 0 | J17: 0 | K17: 3089813 | L17: 1672250 | M17: 0 | N17: 0 | O17: 0 | P17: 1711677 | Q17: 37444 | R17: 0 | S17: 0 | T17: 0 | U17: 0 | V17: 0 | W17: 0 | X17: 0 | Y17: 0 | Z17: =SUM(C17:E17)=B17 -> TRUE | AA17: =SUM(F17:J17)=B17 -> TRUE | AB17: =SUM(K17:O17)=C17 -> TRUE | AC17: =SUM(P17:T17)=D17 -> TRUE
A18: 44368 | B18: 7906696 | C18: 5678848 | D18: 2227848 | E18: 0 | F18: 5550891 | G18: 2355805 | H18: 0 | I18: 0 | J18: 0 | K18: 3373958 | L18: 2304890 | M18: 0 | N18: 0 | O18: 0 | P18: 2176933 | Q18: 50915 | R18: 0 | S18: 0 | T18: 0 | U18: 0 | V18: 0 | W18: 0 | X18: 0 | Y18: 0 | Z18: =SUM(C18:E18)=B18 -> TRUE | AA18: =SUM(F18:J18)=B18 -> TRUE | AB18: =SUM(K18:O18)=C18 -> TRUE | AC18: =SUM(P18:T18)=D18 -> TRUE
A19: 44375 | B19: 9416972 | C19: 6721038 | D19: 2695934 | E19: 0 | F19: 6162132 | G19: 3243387 | H19: 11453 | I19: 0 | J19: 0 | K19: 3524749 | L19: 3184843 | M19: 11446 | N19: 0 | O19: 0 | P19: 2637383 | Q19: 58544 | R19: 7 | S19: 0 | T19: 0 | U19: 0 | V19: 0 | W19: 0 | X19: 0 | Y19: 0 | Z19: =SUM(C19:E19)=B19 -> TRUE | AA19: =SUM(F19:J19)=B19 -> TRUE | AB19: =SUM(K19:O19)=C19 -> TRUE | AC19: =SUM(P19:T19)=D19 -> TRUE
A20: 44382 | B20: 11058390 | C20: 8022029 | D20: 3036361 | E20: 0 | F20: 6619009 | G20: 4306880 | H20: 132501 | I20: 0 | J20: 0 | K20: 3645186 | L20: 4244759 | M20: 132084 | N20: 0 | O20: 0 | P20: 2973823 | Q20: 62121 | R20: 417 | S20: 0 | T20: 0 | U20: 0 | V20: 0 | W20: 0 | X20: 0 | Y20: 0 | Z20: =SUM(C20:E20)=B20 -> TRUE | AA20: =SUM(F20:J20)=B20 -> TRUE | AB20: =SUM(K20:O20)=C20 -> TRUE | AC20: =SUM(P20:T20)=D20 -> TRUE | AG20: =(765906+665129+319009+806588+3907074)/C20 -> 0.80574453 | AH20: =(681274+429170+173981+182108+1468945)/D20 -> 0.96677503 | AJ20: =1558323/C20 -> 0.19425547 | AK20: =100883/D20 -> 0.033224969
A21: 44389 | B21: 12908193 | C21: 9598949 | D21: 3309244 | E21: 0 | F21: 7084913 | G21: 5562669 | H21: 260611 | I21: 0 | J21: 0 | K21: 3841209 | L21: 5497723 | M21: 260017 | N21: 0 | O21: 0 | P21: 3243704 | Q21: 64946 | R21: 594 | S21: 0 | T21: 0 | U21: 0 | V21: 0 | W21: 0 | X21: 0 | Y21: 0 | Z21: =SUM(C21:E21)=B21 -> TRUE | AA21: =SUM(F21:J21)=B21 -> TRUE | AB21: =SUM(K21:O21)=C21 -> TRUE | AC21: =SUM(P21:T21)=D21 -> TRUE
A22: 44396 | B22: 14547244 | C22: 11067518 | D22: 3479726 | E22: 0 | F22: 7608312 | G22: 6463740 | H22: 475192 | I22: 0 | J22: 0 | K22: 4264394 | L22: 6332899 | M22: 470225 | N22: 0 | O22: 0 | P22: 3343918 | Q22: 130841 | R22: 4967 | S22: 0 | T22: 0 | U22: 0 | V22: 0 | W22: 0 | X22: 0 | Y22: 0 | Z22: =SUM(C22:E22)=B22 -> TRUE | AA22: =SUM(F22:J22)=B22 -> TRUE | AB22: =SUM(K22:O22)=C22 -> TRUE | AC22: =SUM(P22:T22)=D22 -> TRUE
A23: 44402 | B23: 15960778 | C23: 12307788 | D23: 3652990 | E23: 0 | F23: 8116637 | G23: 7139026 | H23: 705115 | I23: 0 | J23: 0 | K23: 4730460 | L23: 6913815 | M23: 663513 | N23: 0 | O23: 0 | P23: 3386177 | Q23: 225211 | R23: 41602 | S23: 0 | T23: 0 | U23: 0 | V23: 0 | W23: 0 | X23: 0 | Y23: 0 | Z23: =SUM(C23:E23)=B23 -> TRUE | AA23: =SUM(F23:J23)=B23 -> TRUE | AB23: =SUM(K23:O23)=C23 -> TRUE | AC23: =SUM(P23:T23)=D23 -> TRUE
A24: 44410 | B24: 18198825 | C24: 14207477 | D24: 3991348 | E24: 0 | F24: 8861828 | G24: 8228121 | H24: 1108876 | I24: 0 | J24: 0 | K24: 5446888 | L24: 7857639 | M24: 902950 | N24: 0 | O24: 0 | P24: 3414940 | Q24: 370482 | R24: 205926 | S24: 0 | T24: 0 | U24: 0 | V24: 0 | W24: 0 | X24: 0 | Y24: 0 | Z24: =SUM(C24:E24)=B24 -> TRUE | AA24: =SUM(F24:J24)=B24 -> TRUE | AB24: =SUM(K24:O24)=C24 -> TRUE | AC24: =SUM(P24:T24)=D24 -> TRUE
A25: 44417 | B25: 21171110 | C25: 16336743 | D25: 4566345 | E25: 268022 | F25: 10269135 | G25: 9230417 | H25: 1541724 | I25: 129834 | J25: 0 | K25: 6830715 | L25: 8331186 | M25: 1141623 | N25: 33219 | O25: 0 | P25: 3438420 | Q25: 714202 | R25: 400101 | S25: 13622 | T25: 0 | U25: 0 | V25: 185029 | W25: 0 | X25: 82993 | Y25: 0 | Z25: =SUM(C25:E25)=B25 -> TRUE | AA25: =SUM(F25:J25)=B25 -> TRUE | AB25: =SUM(K25:O25)=C25 -> TRUE | AC25: =SUM(P25:T25)=D25 -> TRUE | AD25: =SUM(U25:Y25)=E25 -> TRUE
A26: 44424 | B26: 24100631 | C26: 18370997 | D26: 5228157 | E26: 501477 | F26: 11399453 | G26: 10255294 | H26: 2036818 | I26: 409066 | J26: 0 | K26: 7949935 | L26: 8911490 | M26: 1429136 | N26: 80436 | O26: 0 | P26: 3449518 | Q26: 1146293 | R26: 607682 | S26: 24664 | T26: 0 | U26: 0 | V26: 197511 | W26: 0 | X26: 303966 | Y26: 0 | Z26: =SUM(C26:E26)=B26 -> TRUE | AA26: =SUM(F26:J26)=B26 -> TRUE | AB26: =SUM(K26:O26)=C26 -> TRUE | AC26: =SUM(P26:T26)=D26 -> TRUE | AD26: =SUM(U26:Y26)=E26 -> TRUE
A27: 44431 | B27: 27612445 | C27: 20830673 | D27: 6230511 | E27: 551261 | F27: 12774822 | G27: 11552009 | H27: 2723850 | I27: 561764 | J27: 0 | K27: 9315125 | L27: 9442786 | M27: 1888983 | N27: 183779 | O27: 0 | P27: 3459697 | Q27: 1905095 | R27: 834867 | S27: 30852 | T27: 0 | U27: 0 | V27: 204128 | W27: 0 | X27: 347133 | Y27: 0 | Z27: =SUM(C27:E27)=B27 -> TRUE | AA27: =SUM(F27:J27)=B27 -> TRUE | AB27: =SUM(K27:O27)=C27 -> TRUE | AC27: =SUM(P27:T27)=D27 -> TRUE | AD27: =SUM(U27:Y27)=E27 -> TRUE
A28: 44438 | B28: 31771819 | C28: 23401465 | D28: 7780973 | E28: 589381 | F28: 14228309 | G28: 13234754 | H28: 3551453 | I28: 757303 | J28: 0 | K28: 10758603 | L28: 9778844 | M28: 2538731 | N28: 325287 | O28: 0 | P28: 3469706 | Q28: 3246755 | R28: 1012722 | S28: 51790 | T28: 0 | U28: 0 | V28: 209155 | W28: 0 | X28: 380226 | Y28: 0 | Z28: =SUM(C28:E28)=B28 -> TRUE | AA28: =SUM(F28:J28)=B28 -> TRUE | AB28: =SUM(K28:O28)=C28 -> TRUE | AC28: =SUM(P28:T28)=D28 -> TRUE | AD28: =SUM(U28:Y28)=E28 -> TRUE
A29: 44445 | B29: 36635271 | C29: 25554456 | D29: 10475325 | E29: 605490 | F29: 15502824 | G29: 15776445 | H29: 4462303 | I29: 893699 | J29: 0 | K29: 12017050 | L29: 9999855 | M29: 3152636 | N29: 384915 | O29: 0 | P29: 3485774 | Q29: 5563895 | R29: 1309667 | S29: 115989 | T29: 0 | U29: 0 | V29: 212695 | W29: 0 | X29: 392795 | Y29: 0 | Z29: =SUM(C29:E29)=B29 -> TRUE | AA29: =SUM(F29:J29)=B29 -> TRUE | AB29: =SUM(K29:O29)=C29 -> TRUE | AC29: =SUM(P29:T29)=D29 -> TRUE | AD29: =SUM(U29:Y29)=E29 -> TRUE
A30: 44452 | B30: 40953025 | C30: 27540743 | D30: 12795707 | E30: 616575 | F30: 16803776 | G30: 17693716 | H30: 5395541 | I30: 1059992 | J30: 0 | K30: 13307382 | L30: 10133924 | M30: 3697794 | N30: 401643 | O30: 0 | P30: 3496394 | Q30: 7342539 | R30: 1697747 | S30: 259027 | T30: 0 | U30: 0 | V30: 217253 | W30: 0 | X30: 399322 | Y30: 0 | Z30: =SUM(C30:E30)=B30 -> TRUE | AA30: =SUM(F30:J30)=B30 -> TRUE | AB30: =SUM(K30:O30)=C30 -> TRUE | AC30: =SUM(P30:T30)=D30 -> TRUE | AD30: =SUM(U30:Y30)=E30 -> TRUE
A31: 44459 | B31: 45211101 | C31: 29201077 | D31: 15388071 | E31: 621953 | F31: 17819695 | G31: 19664100 | H31: 6490255 | I31: 1237051 | J31: 0 | K31: 14319104 | L31: 10213299 | M31: 4251459 | N31: 417215 | P31: 3500591 | Q31: 9231590 | R31: 2238796 | S31: 417094 | T31: 0 | V31: 219211 | X31: 402742 | Z31: =SUM(C31:E31)=B31 -> TRUE | AA31: =SUM(F31:J31)=B31 -> TRUE | AB31: =SUM(K31:O31)=C31 -> TRUE | AC31: =SUM(P31:T31)=D31 -> TRUE | AD31: =SUM(U31:Y31)=E31 -> TRUE
A32: 44473 | B32: 55921443 | C32: 33243525 | D32: 21162251 | E32: 1515667 | F32: 20275031 | G32: 25189881 | H32: 8993912 | I32: 1462619 | J32: 0 | K32: 16763410 | L32: 10414975 | M32: 5610652 | N32: 454488 | O32: 0 | P32: 3511621 | Q32: 13745520 | R32: 3383260 | S32: 521850 | T32: 0 | U32: 0 | V32: 1029386 | W32: 0 | X32: 486281 | Y32: 0 | Z32: =SUM(C32:E32)=B32 -> TRUE | AA32: =SUM(F32:J32)=B32 -> TRUE | AB32: =SUM(K32:O32)=C32 -> TRUE | AC32: =SUM(P32:T32)=D32 -> TRUE | AD32: =SUM(U32:Y32)=E32 -> TRUE
A33: 44480 | B33: 61033251 | C33: 35462170 | D33: 23796497 | E33: 1774584 | F33: 21177859 | G33: 27492935 | H33: 10023635 | I33: 2338822 | J33: 0 | K33: 17663254 | L33: 10471685 | M33: 6019401 | N33: 1307830 | O33: 0 | P33: 3514605 | Q33: 15738545 | R33: 4004234 | S33: 539113 | T33: 0 | U33: 0 | V33: 1282705 | W33: 0 | X33: 491879 | Y33: 0 | Z33: =SUM(C33:E33)=B33 -> TRUE | AA33: =SUM(F33:J33)=B33 -> TRUE | AB33: =SUM(K33:O33)=C33 -> TRUE | AC33: =SUM(P33:T33)=D33 -> TRUE | AD33: =SUM(U33:Y33)=E33 -> TRUE | AE33: =499046/C33 -> 0.01407263 | AF33: =4161/D33 -> 0.00017485767 | AG33: =(878685+1191746+731244+3997965+21537148+71332)/C33 -> 0.80108239 | AH33: =(850685+1057265+640599+2808555+13483779+48076)/D33 -> 0.79377057 | AI33: =(647637+173380+74595+104733+734924+454)/E33 -> 0.97810135 | AJ33: =6555004/C33 -> 0.18484498 | AK33: =4903377/D33 -> 0.20605457 | AL33: =38861/E33 -> 0.021898653
A34: 44487 | B34: 66592321 | C34: 38137096 | D34: 26474522 | E34: 1980703 | F34: 22267275 | G34: 29747511 | H34: 11031696 | I34: 3545839 | J34: 0 | K34: 18747124 | L34: 10557501 | M34: 6331486 | N34: 2500985 | O34: 0 | P34: 3520151 | Q34: 17705332 | R34: 4700210 | S34: 548829 | T34: 0 | U34: 0 | V34: 1484678 | W34: 0 | X34: 496025 | Y34: 0 | Z34: =SUM(C34:E34)=B34 -> TRUE | AA34: =SUM(F34:J34)=B34 -> TRUE | AB34: =SUM(K34:O34)=C34 -> TRUE | AC34: =SUM(P34:T34)=D34 -> TRUE | AD34: =SUM(U34:Y34)=E34 -> TRUE
A35: 44494 | B35: 71237520 | C35: 40346281 | D35: 28713904 | E35: 2177335 | F35: 23247281 | G35: 31673297 | H35: 11795636 | I35: 4521306 | J35: 0 | K35: 19722907 | L35: 10636009 | M35: 6551665 | N35: 3435700 | O35: 0 | P35: 3524374 | Q35: 19372791 | R35: 5243971 | S35: 572768 | T35: 0 | U35: 0 | V35: 1664497 | W35: 0 | X35: 512838 | Y35: 0 | Z35: =SUM(C35:E35)=B35 -> TRUE | AA35: =SUM(F35:J35)=B35 -> TRUE | AB35: =SUM(K35:O35)=C35 -> TRUE | AC35: =SUM(P35:T35)=D35 -> TRUE | AD35: =SUM(U35:Y35)=E35 -> TRUE
A36: 44501 | B36: 76226116 | C36: 42548483 | D36: 31244587 | E36: 2433046 | F36: 24393609 | G36: 33531619 | H36: 12410500 | I36: 5890388 | J36: 0 | K36: 20862351 | L36: 10724547 | M36: 6739348 | N36: 4222237 | O36: 0 | P36: 3531258 | Q36: 20908521 | R36: 5671152 | S36: 1133656 | T36: 0 | U36: 0 | V36: 1898551 | W36: 0 | X36: 534495 | Y36: 0 | Z36: =SUM(C36:E36)=B36 -> TRUE | AA36: =SUM(F36:J36)=B36 -> TRUE | AB36: =SUM(K36:O36)=C36 -> TRUE | AC36: =SUM(P36:T36)=D36 -> TRUE | AD36: =SUM(U36:Y36)=E36 -> TRUE
A37: 44508 | B37: 80968807 | C37: 44116509 | D37: 34240355 | E37: 2611943 | F37: 25167025 | G37: 35467294 | H37: 12995618 | I37: 7338870 | J37: 0 | K37: 21632113 | L37: 10960225 | M37: 6938640 | N37: 4585531 | O37: 0 | P37: 3534912 | Q37: 22461435 | R37: 6056978 | S37: 2187030 | T37: 0 | U37: 0 | V37: 2045634 | W37: 0 | X37: 566309 | Y37: 0 | Z37: =SUM(C37:E37)=B37 -> TRUE | AA37: =SUM(F37:J37)=B37 -> TRUE | AB37: =SUM(K37:O37)=C37 -> TRUE | AC37: =SUM(P37:T37)=D37 -> TRUE | AD37: =SUM(U37:Y37)=E37 -> TRUE
A38: 44515 | B38: 85412126 | C38: 45488767 | D38: 37114546 | E38: 2808813 | F38: 25707526 | G38: 37670153 | H38: 13407610 | I38: 8626837 | J38: 0 | K38: 22166237 | L38: 11409714 | M38: 7068775 | N38: 4844041 | O38: 0 | P38: 3541289 | Q38: 24070438 | R38: 6338835 | S38: 3163984 | T38: 0 | U38: 0 | V38: 2190001 | W38: 0 | X38: 618812 | Y38: 0 | Z38: =SUM(C38:E38)=B38 -> TRUE | AA38: =SUM(F38:J38)=B38 -> TRUE | AB38: =SUM(K38:O38)=C38 -> TRUE | AC38: =SUM(P38:T38)=D38 -> TRUE | AD38: =SUM(U38:Y38)=E38 -> TRUE
A39: 44522 | B39: 89336791 | C39: 46836876 | D39: 39403769 | E39: 3096146 | F39: 25976355 | G39: 39739566 | H39: 13738840 | I39: 9606282 | J39: 275748 | K39: 22428746 | L39: 12057856 | M39: 7186742 | N39: 5019276 | O39: 144256 | P39: 3547609 | Q39: 25367343 | R39: 6552098 | S39: 3910689 | T39: 26030 | U39: 0 | V39: 2314367 | W39: 0 | X39: 676317 | Y39: 105462 | Z39: =SUM(C39:E39)=B39 -> TRUE | AA39: =SUM(F39:J39)=B39 -> TRUE | AB39: =SUM(K39:O39)=C39 -> TRUE | AC39: =SUM(P39:T39)=D39 -> TRUE | AD39: =SUM(U39:Y39)=E39 -> TRUE
A40: 44529 | B40: 92658390 | C40: 48074050 | D40: 41210777 | E40: 3373563 | F40: 26149698 | G40: 41599293 | H40: 13988065 | I40: 10483755 | J40: 437579 | K40: 22596654 | L40: 12702788 | M40: 7270185 | N40: 5288812 | O40: 215611 | P40: 3553044 | Q40: 26439285 | R40: 6717880 | S40: 4443951 | T40: 56617 | U40: 0 | V40: 2457220 | W40: 0 | X40: 750992 | Y40: 165351 | Z40: =SUM(C40:E40)=B40 -> TRUE | AA40: =SUM(F40:J40)=B40 -> TRUE | AB40: =SUM(K40:O40)=C40 -> TRUE | AC40: =SUM(P40:T40)=D40 -> TRUE | AD40: =SUM(U40:Y40)=E40 -> TRUE
...

Sheet date_vaccination
B1: start_date_first | C1: start_date_second
A2: Sinovac | B2: 44255 | C2: 44277 | D2: 4 week schedule
A3: AZ | B3: 44284 | C3: 44333 | D3: 8-10 week schedule
A4: Sinopharm | B4: 44375 | C4: 44375
A5: Booster | B5: 44417
A6: Pfizer | B6: 44417
A7: Moderna | B7: 44522
